Workbook
Name Set_Year: SETTINGS!$C$7
Name Set_ChristmasDate: SETTINGS!$C$8
Name Set_SeasonStart: SETTINGS!$C$9
Name Set_Currency: SETTINGS!$C$10
Name Set_Household: SETTINGS!$C$11
Name Set_WarnThreshold: SETTINGS!$C$12
Name Set_ShipWindow: SETTINGS!$C$13
Name Set_LowStock: SETTINGS!$C$14
Name Set_WeekStart: SETTINGS!$C$15
Name Set_Edition: SETTINGS!$C$16
Name List_Currency: LISTS!$B$8:$B$12
Name List_WeekStart: LISTS!$C$8:$C$9
Name List_YesNo: LISTS!$D$8:$D$9
Name List_Group: LISTS!$E$8:$E$16
Name List_BudgetCategory: LISTS!$F$8:$F$19
Name List_GiftStatus: LISTS!$G$8:$G$13
Name List_GiftType: LISTS!$H$8:$H$10
Name List_DeliveryType: LISTS!$I$8:$I$12
Name List_Priority: LISTS!$J$8:$J$10
Name List_OrderStatus: LISTS!$K$8:$K$13
Name List_IssueType: LISTS!$L$8:$L$13
Name List_ReturnStatus: LISTS!$M$8:$M$13
Name List_CalendarType: LISTS!$N$8:$N$13
Name List_CalendarStatus: LISTS!$O$8:$O$13
Name List_VendorCategory: LISTS!$P$8:$P$17
Name List_VendorStatus: LISTS!$Q$8:$Q$14
Name List_DecorCategory: LISTS!$R$8:$R$19
Name List_Condition: LISTS!$S$8:$S$12
Name List_Room: LISTS!$T$8:$T$18
Name List_ApprovalStatus: LISTS!$U$8:$U$11
Name List_Course: LISTS!$V$8:$V$16
Name List_MealStatus: LISTS!$W$8:$W$13
Name List_DietaryTag: LISTS!$X$8:$X$17
Name List_GroceryCategory: LISTS!$Y$8:$Y$18
Name List_RecipeCategory: LISTS!$Z$8:$Z$15
Name List_GuestStatus: LISTS!$AA$8:$AA$13
Name List_Sleeping: LISTS!$AB$8:$AB$13
Name List_TraditionCategory: LISTS!$AC$8:$AC$15
Name List_MediaType: LISTS!$AD$8:$AD$14
Name List_Audience: LISTS!$AE$8:$AE$12
Name List_CardStatus: LISTS!$AF$8:$AF$13
Name List_AddressStatus: LISTS!$AG$8:$AG$11
Name List_WardrobeStatus: LISTS!$AH$8:$AH$12
Name List_TravelType: LISTS!$AI$8:$AI$15
Name List_BookingStatus: LISTS!$AJ$8:$AJ$13
Name List_Recurrence: LISTS!$AK$8:$AK$13
Name List_TaskStatus: LISTS!$AL$8:$AL$12
Name List_GivingType: LISTS!$AM$8:$AM$12
Name List_Ownership: LISTS!$AN$8:$AN$11
Name List_Rating: LISTS!$AO$8:$AO$12
Name List_NextYearTheme: LISTS!$AP$8:$AP$14
Name List_Relationship: LISTS!$AQ$8:$AQ$20
Name Vision_Theme: 'SEASON VISION'!$C$7
Name Vision_Feelings: 'SEASON VISION'!$C$8
Name Vision_Colours: 'SEASON VISION'!$C$9
Name Vision_Scent: 'SEASON VISION'!$C$10
Name Vision_Protect: 'SEASON VISION'!$C$11
Name QA_Exceptions: 'QUALITY CHECK'!$C$91

Sheet COVER
B6: A PRIVATE CHRISTMAS ATELIER
B9: The Christmas Season
B12: Master Command Center
B17: Curate every exquisite detail in one private Christmas atelier.
B20: =IF(Set_Household="","Welcome.","For the "&Set_Household&" household.")
B22: ="Christmas "&Set_Year&" · "&MAX(0,Set_ChristmasDate-TODAY())&" days to go"
B25: Begin here → START HERE
B26: Straight to the dashboard → DASHBOARD
B32: ="Edition "&Set_Edition&" · Google Sheets edition"
B33: [SELLER BRAND] · For your own household. Not for resale, redistribution or sharing.
B34: See TERMS OF USE, included with your download, for the full licence.

Sheet START HERE
B1: Dashboard | D1: Start here | F1: Calendar | H1: Budget | J1: All sheets
B2: Start here
B3: Six steps, ten minutes, and the rest of the season has somewhere to live.
B6: Setting up
B8: 1 | C8: Save a clean copy first
C9: Before you type anything, save a copy called “master”. Come next year you will want an empty one to start from.
B11: 2 | C11: Set up SETTINGS
C12: Year, Christmas date, season start, currency and household name. Everything else reads from there.
B14: 3 | C14: Add people before gifts
C15: Fill in PEOPLE + BUDGETS, then RECIPIENT PROFILES if you like keeping notes. Gift rows attach to a Person ID.
B17: 4 | C17: Choose your modules
C18: Use what suits you. TRAVEL PLAN, ADVENT + REFLECTION and MOVIES + MUSIC hide cleanly — right-click the tab and choose Hide.
B20: 5 | C20: Write the season vision
C21: Five lines on SEASON VISION, and the first few dates on CHRISTMAS CALENDAR.
B23: 6 | C23: Go to the dashboard
C24: It will tell you what is unfinished. Work down the attention board; that is the whole method.
B27: What the colours mean
C29: Cream | D29: Yours to fill in.
C30: Pale green | D30: Calculates itself. Locked so it cannot be typed over by accident.
C31: Amber | D31: Either an example row to delete, or something asking for attention.
C32: Rose | D32: Over budget, overdue or late. Read the word in the cell — the colour is never the whole story.
C34: Every colour is backed by a word. If you cannot see the fill, the cell still says OVERDUE, NEAR LIMIT or ON TRACK.
B37: Working in the workbook
B39: Filters | D39: Every tracker has them, on the header row. Filter, do not delete.
B40: Sorting | D40: Safe. IDs are typed text, not row numbers, so nothing comes unstuck when you re-order a table.
B41: Adding rows | D41: Insert a row inside the table — click a row in the middle, not the one after the last. Formulas and dropdowns come with it. Then copy a calculated cell down into the new row.
B42: Dropdown lists | D42: They live on LISTS. To add a value, insert a row inside the block rather than below it, and every dropdown that uses it widens automatically.
B43: Hiding a module | D43: Right-click the tab and choose Hide. Nothing breaks: every total reads an empty sheet as zero.
B44: Unprotecting | D44: Review, then Unprotect Sheet. There is no password. The lock is only there to stop a calculation being typed over by accident.
B45: Examples | D45: Three amber rows on each tracker, every one marked EXAMPLE — DELETE ME. Delete the contents when you are ready; deleting them breaks nothing.
B46: Printing | D46: The dashboard prints as two pages. A tracker prints its first columns — the ones worth carrying to the shops — at full size. To print the whole table instead, go to Page Layout, Print Area, Clear. Filter the sheet first either way, or you will print every empty row.
B49: Putting the year away
B51: 1. | C51: Save this year’s workbook under its own name — “Christmas 2026”, and leave it alone.
B52: 2. | C52: Open your clean master copy, or copy the figures below into ANNUAL ARCHIVE before you clear anything.
B53: 3. | C53: From MASTER BUDGET copy the Budget and Actual totals; from the dashboard, gifts given and guests hosted.
B54: 4. | C54: Delete the contents of the cream cells on each tracker. Do not delete rows, and do not touch the pale green columns.
B55: 5. | C55: Update the year on SETTINGS. The countdown, the calendar and every label follow it.
B56: 6. | C56: Read NEXT YEAR NOTES before you plan anything. That is what it was for.
B59: A note on what you keep here
B61: This is an ordinary spreadsheet on your own device. It is not encrypted, and anyone who opens the file can read it. Keep hiding places, sizes and preferences here if they help you plan. Keep card numbers, passwords and identity documents somewhere else.
...

Sheet SETTINGS
B1: Dashboard | C1: Start here | D1: Calendar | E1: Budget | F1: All sheets
B2: Settings
B3: Nine decisions the whole workbook reads from. Set them once, at the start of the season.
B4: Cream cells are yours · the edition below is fixed · everything else in the workbook follows these values
B7: Christmas year | C7: 2026 | D7: The season this copy of the workbook plans. Change it once, at the start of the season.
B8: Christmas date | C8: 46381 | D8: Defaults to 25 December of the year above. Edit only if you keep Christmas on another day.
B9: Season start | C9: 46266 | D9: The date your planning calendar opens. 1 September by default.
B10: Currency symbol | C10: CAD | D10: Sets the symbol shown beside every amount.
B11: Household / planner name | D11: Used in the welcome line on the cover and dashboard. Leave blank if you prefer.
B12: Budget warning threshold | C12: 0.9 | D12: The share of a budget that turns a category amber. 90% by default.
B13: Shipping risk window (days) | C13: 7 | D13: How many days before an expected delivery an order without tracking starts asking for attention.
B14: Low-stock threshold | C14: 1 | D14: Décor quantity at or below this prompts a replacement note.
B15: Week starts | C15: Sunday | D15: Sunday or Monday, for calendar week numbers.
B16: Edition | C16: 1.0 | D16: The version of this workbook. Quote it if you contact support.
B19: What these change
B21: Christmas year | C21: The countdown, every label that names the year, and the default Christmas date.
B22: Budget warning threshold | C22: When a category turns amber instead of green. Lower it if you want warning sooner.
B23: Shipping risk window | C23: How many days out an order with no tracking starts asking to be chased.
B24: Low-stock threshold | C24: When DÉCOR INVENTORY says LOW rather than IN STOCK.
B25: Currency symbol | C25: The symbol on every amount. It does not convert anything — one workbook, one currency.

Sheet DASHBOARD
B1: Dashboard | D1: Start here | G1: Calendar | I1: Budget | K1: All sheets
B2: Dashboard
B3: =IF(Set_Household="","Christmas "&Set_Year&" — where everything stands today.","Christmas "&Set_Year&" for the "&Set_Household&" household — where everything stands today.")
B4: Every figure below is calculated. Follow a card to its sheet using the strip above, or the SHEET INDEX.
B6: DAYS TO CHRISTMAS | F6: BUDGET SET | J6: SPENT SO FAR | N6: REMAINING
B7: =MAX(0,Set_ChristmasDate-TODAY()) | F7: =SUM('MASTER BUDGET'!$E$6:$E$25) | J7: =SUM('MASTER BUDGET'!$G$6:$G$25) | N7: =SUM('MASTER BUDGET'!$E$6:$E$25)-SUM('MASTER BUDGET'!$G$6:$G$25)
B9: ="Christmas falls on "&TEXT(Set_ChristmasDate,"dddd d mmmm") | F9: The total of every category on MASTER BUDGET. | J9: ="Planned, including what you have not bought yet: "&TEXT(SUM('MASTER BUDGET'!$F$6:$F$25),"""$""#,##0.00;[Red]-""$""#,##0.00;""$""—") | N9: =IF(SUM('MASTER BUDGET'!$E$6:$E$25)=0,"No budget set yet.",IF(SUM('MASTER BUDGET'!$E$6:$E$25)-SUM('MASTER BUDGET'!$G$6:$G$25)<0,"OVER BUDGET — see MASTER BUDGET.","Against the budget you set."))
B11: GIFTS CHOSEN | F11: WRAPPED | J11: DELIVERED | N11: ON THE LIST
B12: =IF(COUNTIFS('GIFT PLANNER'!$E$6:$E$205,"Yes")=0,0,COUNTIFS('GIFT PLANNER'!$E$6:$E$205,"Yes",'GIFT PLANNER'!$T$6:$T$205,"Yes")/COUNTIFS('GIFT PLANNER'!$E$6:$E$205,"Yes")) | F12: =IF(COUNTIFS('GIFT PLANNER'!$E$6:$E$205,"Yes",'GIFT PLANNER'!$T$6:$T$205,"Yes",'GIFT PLANNER'!$Y$6:$Y$205,"Physical")=0,0,COUNTIFS('GIFT PLANNER'!$E$6:$E$205,"Yes",'GIFT PLANNER'!$T$6:$T$205,"Yes",'GIFT PLANNER'!$Y$6:$Y$205,"Physical",'GIFT PLANNER'!$Z$6:$Z$205,"Yes")/COUNTIFS('GIFT PLANNER'!$E$6:$E$205,"Yes",'GIFT PLANNER'!$T$6:$T$205,"Yes",'GIFT PLANNER'!$Y$6:$Y$205,"Physical")) | J12: =IF(COUNTIFS('ONLINE ORDERS'!$B$6:$B$155,"?*",'ONLINE ORDERS'!$K$6:$K$155,"<>Cancelled")=0,0,COUNTIFS('ONLINE ORDERS'!$B$6:$B$155,"?*",'ONLINE ORDERS'!$K$6:$K$155,"<>Cancelled",'ONLINE ORDERS'!$M$6:$M$155,"Yes")/COUNTIFS('ONLINE ORDERS'!$B$6:$B$155,"?*",'ONLINE ORDERS'!$K$6:$K$155,"<>Cancelled")) | N12: =IF(COUNTIFS('CHRISTMAS CALENDAR'!$B$6:$B$205,"?*",'CHRISTMAS CALENDAR'!$Q$6:$Q$205,"Yes")+COUNTIFS('CHRISTMAS CALENDAR'!$B$6:$B$205,"?*",'CHRISTMAS CALENDAR'!$Q$6:$Q$205,"No")=0,0,COUNTIFS('CHRISTMAS CALENDAR'!$B$6:$B$205,"?*",'CHRISTMAS CALENDAR'!$Q$6:$Q$205,"No")/(COUNTIFS('CHRISTMAS CALENDAR'!$B$6:$B$205,"?*",'CHRISTMAS CALENDAR'!$Q$6:$Q$205,"Yes")+COUNTIFS('CHRISTMAS CALENDAR'!$B$6:$B$205,"?*",'CHRISTMAS CALENDAR'!$Q$6:$Q$205,"No")))
B14: =IF(COUNTIFS('GIFT PLANNER'!$E$6:$E$205,"Yes")=0,"Not started.",COUNTIFS('GIFT PLANNER'!$E$6:$E$205,"Yes",'GIFT PLANNER'!$T$6:$T$205,"Yes")&" of "&COUNTIFS('GIFT PLANNER'!$E$6:$E$205,"Yes")&" bought") | F14: =IF(COUNTIFS('GIFT PLANNER'!$E$6:$E$205,"Yes",'GIFT PLANNER'!$T$6:$T$205,"Yes",'GIFT PLANNER'!$Y$6:$Y$205,"Physical")=0,"Nothing to wrap yet.",COUNTIFS('GIFT PLANNER'!$E$6:$E$205,"Yes",'GIFT PLANNER'!$T$6:$T$205,"Yes",'GIFT PLANNER'!$Y$6:$Y$205,"Physical",'GIFT PLANNER'!$Z$6:$Z$205,"Yes")&" of "&COUNTIFS('GIFT PLANNER'!$E$6:$E$205,"Yes",'GIFT PLANNER'!$T$6:$T$205,"Yes",'GIFT PLANNER'!$Y$6:$Y$205,"Physical")&" — digital and experience gifts are not counted") | J14: =IF(COUNTIFS('ONLINE ORDERS'!$B$6:$B$155,"?*",'ONLINE ORDERS'!$K$6:$K$155,"<>Cancelled")=0,"No orders yet.",COUNTIFS('ONLINE ORDERS'!$B$6:$B$155,"?*",'ONLINE ORDERS'!$K$6:$K$155,"<>Cancelled")-COUNTIFS('ONLINE ORDERS'!$B$6:$B$155,"?*",'ONLINE ORDERS'!$K$6:$K$155,"<>Cancelled",'ONLINE ORDERS'!$M$6:$M$155,"Yes")&" still on their way") | N14: =IF(COUNTIFS('CHRISTMAS CALENDAR'!$B$6:$B$205,"?*",'CHRISTMAS CALENDAR'!$Q$6:$Q$205,"Yes")+COUNTIFS('CHRISTMAS CALENDAR'!$B$6:$B$205,"?*",'CHRISTMAS CALENDAR'!$Q$6:$Q$205,"No")=0,"Nothing in the calendar yet.",COUNTIFS('CHRISTMAS CALENDAR'!$B$6:$B$205,"?*",'CHRISTMAS CALENDAR'!$Q$6:$Q$205,"Yes")&" still open")
B16: What needs you | J16: This season
B17: =COUNTIF('MASTER BUDGET'!$J$6:$J$25,"OVER BUDGET") | C17: categories over budget | G17: MASTER BUDGET | J17: This year is for | L17: =IF(Vision_Theme="","Write one line on SEASON VISION.",Vision_Theme)
B18: =COUNTIF('MASTER BUDGET'!$J$6:$J$25,"NEAR LIMIT") | C18: categories near their limit | G18: MASTER BUDGET | J18: It should feel | L18: =IF(Vision_Feelings="","—",Vision_Feelings)
B19: =COUNTIFS('GIFT PLANNER'!$E$6:$E$205,"Yes",'GIFT PLANNER'!$T$6:$T$205,"No") | C19: gifts still to choose or buy | G19: GIFT PLANNER | J19: First priority | L19: =IFERROR(INDEX('SEASON VISION'!$C$15:$C$38,MATCH("?*",'SEASON VISION'!$C$15:$C$38,0)),"Nothing written yet.")
B20: =COUNTIFS('GIFT PLANNER'!$E$6:$E$205,"Yes",'GIFT PLANNER'!$T$6:$T$205,"Yes",'GIFT PLANNER'!$Y$6:$Y$205,"Physical",'GIFT PLANNER'!$Z$6:$Z$205,"<>Yes") | C20: bought gifts not yet wrapped | G20: GIFT PLANNER | J20: Next tradition | L20: =IF(MIN('TRADITIONS + BUCKET LIST'!$P$6:$P$85)=0,"Nothing dated yet.",IFERROR(INDEX('TRADITIONS + BUCKET LIST'!$C$6:$C$85,MATCH(MIN('TRADITIONS + BUCKET LIST'!$P$6:$P$85),'TRADITIONS + BUCKET LIST'!$P$6:$P$85,0)),"")&" — "&TEXT(MIN('TRADITIONS + BUCKET LIST'!$P$6:$P$85),"d mmm"))
B21: =COUNTIF('ONLINE ORDERS'!$R$6:$R$155,"LATE") | C21: orders running late | G21: ONLINE ORDERS | J21: Protecting | L21: =IF(Vision_Protect="","—",Vision_Protect)
B22: =COUNTIF('ONLINE ORDERS'!$R$6:$R$155,"NO TRACKING") | C22: orders with no tracking yet | G22: ONLINE ORDERS
B23: =COUNTIF('ONLINE ORDERS'!$R$6:$R$155,"MISSING DATE") | C23: orders with no expected date | G23: ONLINE ORDERS | J23: The next seven days
B24: =COUNTIF('ONLINE ORDERS'!$S$6:$S$155,"CLOSING SOON") | C24: return windows closing this week | G24: ONLINE ORDERS | J24: =IFERROR(INT(SMALL('CHRISTMAS CALENDAR'!$T$6:$T$205,1)),"") | L24: =IFERROR(INDEX('CHRISTMAS CALENDAR'!$F$6:$F$205,MATCH(SMALL('CHRISTMAS CALENDAR'!$T$6:$T$205,1),'CHRISTMAS CALENDAR'!$T$6:$T$205,0)),IF(1=1,"Nothing in the next seven days.",""))
B25: =COUNTIFS('RETURNS + EXCHANGES'!$B$6:$B$65,"?*",'RETURNS + EXCHANGES'!$P$6:$P$65,"<>Yes",'RETURNS + EXCHANGES'!$O$6:$O$65,">0") | C25: refunds owed to you | G25: RETURNS + EXCHANGES | J25: =IFERROR(INT(SMALL('CHRISTMAS CALENDAR'!$T$6:$T$205,2)),"") | L25: =IFERROR(INDEX('CHRISTMAS CALENDAR'!$F$6:$F$205,MATCH(SMALL('CHRISTMAS CALENDAR'!$T$6:$T$205,2),'CHRISTMAS CALENDAR'!$T$6:$T$205,0)),IF(2=1,"Nothing in the next seven days.",""))
B26: =COUNTIF('CHRISTMAS CALENDAR'!$R$6:$R$205,"OVERDUE") | C26: tasks and events overdue | G26: CHRISTMAS CALENDAR | J26: =IFERROR(INT(SMALL('CHRISTMAS CALENDAR'!$T$6:$T$205,3)),"") | L26: =IFERROR(INDEX('CHRISTMAS CALENDAR'!$F$6:$F$205,MATCH(SMALL('CHRISTMAS CALENDAR'!$T$6:$T$205,3),'CHRISTMAS CALENDAR'!$T$6:$T$205,0)),IF(3=1,"Nothing in the next seven days.",""))
B27: =COUNTIF('GROCERY LIST'!$P$6:$P$205,"TO BUY") | C27: things still to buy for the table | G27: GROCERY LIST | J27: =IFERROR(INT(SMALL('CHRISTMAS CALENDAR'!$T$6:$T$205,4)),"") | L27: =IFERROR(INDEX('CHRISTMAS CALENDAR'!$F$6:$F$205,MATCH(SMALL('CHRISTMAS CALENDAR'!$T$6:$T$205,4),'CHRISTMAS CALENDAR'!$T$6:$T$205,0)),IF(4=1,"Nothing in the next seven days.",""))
B28: =QA_Exceptions | C28: items on QUALITY CHECK | G28: QUALITY CHECK | J28: =IFERROR(INT(SMALL('CHRISTMAS CALENDAR'!$T$6:$T$205,5)),"") | L28: =IFERROR(INDEX('CHRISTMAS CALENDAR'!$F$6:$F$205,MATCH(SMALL('CHRISTMAS CALENDAR'!$T$6:$T$205,5),'CHRISTMAS CALENDAR'!$T$6:$T$205,0)),IF(5=1,"Nothing in the next seven days.",""))
J29: =IFERROR(INT(SMALL('CHRISTMAS CALENDAR'!$T$6:$T$205,6)),"") | L29: =IFERROR(INDEX('CHRISTMAS CALENDAR'!$F$6:$F$205,MATCH(SMALL('CHRISTMAS CALENDAR'!$T$6:$T$205,6),'CHRISTMAS CALENDAR'!$T$6:$T$205,0)),IF(6=1,"Nothing in the next seven days.",""))
B31: Where the money is going | J31: How far along you are
B58: Chart data — calculated. Safe to ignore; it is what the two charts above read.
B59: Category | D59: Budget | E59: Spent | J59: Progress | L59: Done
B60: =IFERROR(INDEX('MASTER BUDGET'!$D$6:$D$25,MATCH(LARGE('MASTER BUDGET'!$L$6:$L$25,1),'MASTER BUDGET'!$L$6:$L$25,0)),"") | D60: =IFERROR(INDEX('MASTER BUDGET'!$E$6:$E$25,MATCH(LARGE('MASTER BUDGET'!$L$6:$L$25,1),'MASTER BUDGET'!$L$6:$L$25,0)),0) | E60: =IFERROR(INDEX('MASTER BUDGET'!$G$6:$G$25,MATCH(LARGE('MASTER BUDGET'!$L$6:$L$25,1),'MASTER BUDGET'!$L$6:$L$25,0)),0) | J60: Gifts chosen | L60: =IF(COUNTIFS('GIFT PLANNER'!$E$6:$E$205,"Yes")=0,0,COUNTIFS('GIFT PLANNER'!$E$6:$E$205,"Yes",'GIFT PLANNER'!$T$6:$T$205,"Yes")/COUNTIFS('GIFT PLANNER'!$E$6:$E$205,"Yes"))
B61: =IFERROR(INDEX('MASTER BUDGET'!$D$6:$D$25,MATCH(LARGE('MASTER BUDGET'!$L$6:$L$25,2),'MASTER BUDGET'!$L$6:$L$25,0)),"") | D61: =IFERROR(INDEX('MASTER BUDGET'!$E$6:$E$25,MATCH(LARGE('MASTER BUDGET'!$L$6:$L$25,2),'MASTER BUDGET'!$L$6:$L$25,0)),0) | E61: =IFERROR(INDEX('MASTER BUDGET'!$G$6:$G$25,MATCH(LARGE('MASTER BUDGET'!$L$6:$L$25,2),'MASTER BUDGET'!$L$6:$L$25,0)),0) | J61: Wrapped | L61: =IF(COUNTIFS('GIFT PLANNER'!$E$6:$E$205,"Yes",'GIFT PLANNER'!$T$6:$T$205,"Yes",'GIFT PLANNER'!$Y$6:$Y$205,"Physical")=0,0,COUNTIFS('GIFT PLANNER'!$E$6:$E$205,"Yes",'GIFT PLANNER'!$T$6:$T$205,"Yes",'GIFT PLANNER'!$Y$6:$Y$205,"Physical",'GIFT PLANNER'!$Z$6:$Z$205,"Yes")/COUNTIFS('GIFT PLANNER'!$E$6:$E$205,"Yes",'GIFT PLANNER'!$T$6:$T$205,"Yes",'GIFT PLANNER'!$Y$6:$Y$205,"Physical"))
B62: =IFERROR(INDEX('MASTER BUDGET'!$D$6:$D$25,MATCH(LARGE('MASTER BUDGET'!$L$6:$L$25,3),'MASTER BUDGET'!$L$6:$L$25,0)),"") | D62: =IFERROR(INDEX('MASTER BUDGET'!$E$6:$E$25,MATCH(LARGE('MASTER BUDGET'!$L$6:$L$25,3),'MASTER BUDGET'!$L$6:$L$25,0)),0) | E62: =IFERROR(INDEX('MASTER BUDGET'!$G$6:$G$25,MATCH(LARGE('MASTER BUDGET'!$L$6:$L$25,3),'MASTER BUDGET'!$L$6:$L$25,0)),0) | J62: Delivered | L62: =IF(COUNTIFS('ONLINE ORDERS'!$B$6:$B$155,"?*",'ONLINE ORDERS'!$K$6:$K$155,"<>Cancelled")=0,0,COUNTIFS('ONLINE ORDERS'!$B$6:$B$155,"?*",'ONLINE ORDERS'!$K$6:$K$155,"<>Cancelled",'ONLINE ORDERS'!$M$6:$M$155,"Yes")/COUNTIFS('ONLINE ORDERS'!$B$6:$B$155,"?*",'ONLINE ORDERS'!$K$6:$K$155,"<>Cancelled"))
B63: =IFERROR(INDEX('MASTER BUDGET'!$D$6:$D$25,MATCH(LARGE('MASTER BUDGET'!$L$6:$L$25,4),'MASTER BUDGET'!$L$6:$L$25,0)),"") | D63: =IFERROR(INDEX('MASTER BUDGET'!$E$6:$E$25,MATCH(LARGE('MASTER BUDGET'!$L$6:$L$25,4),'MASTER BUDGET'!$L$6:$L$25,0)),0) | E63: =IFERROR(INDEX('MASTER BUDGET'!$G$6:$G$25,MATCH(LARGE('MASTER BUDGET'!$L$6:$L$25,4),'MASTER BUDGET'!$L$6:$L$25,0)),0) | J63: On the list | L63: =IF(COUNTIFS('CHRISTMAS CALENDAR'!$B$6:$B$205,"?*",'CHRISTMAS CALENDAR'!$Q$6:$Q$205,"Yes")+COUNTIFS('CHRISTMAS CALENDAR'!$B$6:$B$205,"?*",'CHRISTMAS CALENDAR'!$Q$6:$Q$205,"No")=0,0,COUNTIFS('CHRISTMAS CALENDAR'!$B$6:$B$205,"?*",'CHRISTMAS CALENDAR'!$Q$6:$Q$205,"No")/(COUNTIFS('CHRISTMAS CALENDAR'!$B$6:$B$205,"?*",'CHRISTMAS CALENDAR'!$Q$6:$Q$205,"Yes")+COUNTIFS('CHRISTMAS CALENDAR'!$B$6:$B$205,"?*",'CHRISTMAS CALENDAR'!$Q$6:$Q$205,"No")))
B64: =IFERROR(INDEX('MASTER BUDGET'!$D$6:$D$25,MATCH(LARGE('MASTER BUDGET'!$L$6:$L$25,5),'MASTER BUDGET'!$L$6:$L$25,0)),"") | D64: =IFERROR(INDEX('MASTER BUDGET'!$E$6:$E$25,MATCH(LARGE('MASTER BUDGET'!$L$6:$L$25,5),'MASTER BUDGET'!$L$6:$L$25,0)),0) | E64: =IFERROR(INDEX('MASTER BUDGET'!$G$6:$G$25,MATCH(LARGE('MASTER BUDGET'!$L$6:$L$25,5),'MASTER BUDGET'!$L$6:$L$25,0)),0)
B65: =IFERROR(INDEX('MASTER BUDGET'!$D$6:$D$25,MATCH(LARGE('MASTER BUDGET'!$L$6:$L$25,6),'MASTER BUDGET'!$L$6:$L$25,0)),"") | D65: =IFERROR(INDEX('MASTER BUDGET'!$E$6:$E$25,MATCH(LARGE('MASTER BUDGET'!$L$6:$L$25,6),'MASTER BUDGET'!$L$6:$L$25,0)),0) | E65: =IFERROR(INDEX('MASTER BUDGET'!$G$6:$G$25,MATCH(LARGE('MASTER BUDGET'!$L$6:$L$25,6),'MASTER BUDGET'!$L$6:$L$25,0)),0)
B66: =IFERROR(INDEX('MASTER BUDGET'!$D$6:$D$25,MATCH(LARGE('MASTER BUDGET'!$L$6:$L$25,7),'MASTER BUDGET'!$L$6:$L$25,0)),"") | D66: =IFERROR(INDEX('MASTER BUDGET'!$E$6:$E$25,MATCH(LARGE('MASTER BUDGET'!$L$6:$L$25,7),'MASTER BUDGET'!$L$6:$L$25,0)),0) | E66: =IFERROR(INDEX('MASTER BUDGET'!$G$6:$G$25,MATCH(LARGE('MASTER BUDGET'!$L$6:$L$25,7),'MASTER BUDGET'!$L$6:$L$25,0)),0)
B67: =IFERROR(INDEX('MASTER BUDGET'!$D$6:$D$25,MATCH(LARGE('MASTER BUDGET'!$L$6:$L$25,8),'MASTER BUDGET'!$L$6:$L$25,0)),"") | D67: =IFERROR(INDEX('MASTER BUDGET'!$E$6:$E$25,MATCH(LARGE('MASTER BUDGET'!$L$6:$L$25,8),'MASTER BUDGET'!$L$6:$L$25,0)),0) | E67: =IFERROR(INDEX('MASTER BUDGET'!$G$6:$G$25,MATCH(LARGE('MASTER BUDGET'!$L$6:$L$25,8),'MASTER BUDGET'!$L$6:$L$25,0)),0)
B68: =IFERROR(INDEX('MASTER BUDGET'!$D$6:$D$25,MATCH(LARGE('MASTER BUDGET'!$L$6:$L$25,9),'MASTER BUDGET'!$L$6:$L$25,0)),"") | D68: =IFERROR(INDEX('MASTER BUDGET'!$E$6:$E$25,MATCH(LARGE('MASTER BUDGET'!$L$6:$L$25,9),'MASTER BUDGET'!$L$6:$L$25,0)),0) | E68: =IFERROR(INDEX('MASTER BUDGET'!$G$6:$G$25,MATCH(LARGE('MASTER BUDGET'!$L$6:$L$25,9),'MASTER BUDGET'!$L$6:$L$25,0)),0)
B69: =IFERROR(INDEX('MASTER BUDGET'!$D$6:$D$25,MATCH(LARGE('MASTER BUDGET'!$L$6:$L$25,10),'MASTER BUDGET'!$L$6:$L$25,0)),"") | D69: =IFERROR(INDEX('MASTER BUDGET'!$E$6:$E$25,MATCH(LARGE('MASTER BUDGET'!$L$6:$L$25,10),'MASTER BUDGET'!$L$6:$L$25,0)),0) | E69: =IFERROR(INDEX('MASTER BUDGET'!$G$6:$G$25,MATCH(LARGE('MASTER BUDGET'!$L$6:$L$25,10),'MASTER BUDGET'!$L$6:$L$25,0)),0)

Sheet SEASON VISION
B1: Dashboard | D1: Start here | E1: Calendar | F1: Budget | G1: All sheets
B2: SEASON VISION
B3: What you want this Christmas to feel like, written down before the list-making starts.
B4: Cream cells are yours to fill in · pale green cells calculate themselves · amber rows are examples you can delete
B6: The season in five lines
B7: This year's theme | C7: Quieter, warmer, fewer things
B8: Three words for how it should feel | C8: Unhurried · candlelit · generous
B9: Colour story | C9: Evergreen, ivory, one note of oxblood
B10: Scent and sound | C10: Bitter orange, woodsmoke, the old carols
B11: What you are protecting this year | C11: The mornings. Nothing booked before eleven.
B12: The amber lines above are examples — write over them. The dashboard shows the theme, the feeling and the first priority below.
B14: Priority ID | C14: Priority | D14: Why it matters | E14: Owner | F14: Non-negotiable? | G14: Inspiration link | H14: Notes | I14: QA · duplicate ID
B15: VN-001 | C15: Christmas Eve supper with only the six of us | D15: It is the part everyone remembers | E15: Me | F15: Yes | H15: EXAMPLE — DELETE ME | I15: =IF($B15="",0,IF(COUNTIF('SEASON VISION'!$B$15:$B$38,$B15)>1,1,0))
B16: VN-002 | C16: Every gift chosen by the end of November | D16: December should be for people, not parcels | E16: Me | F16: Yes | H16: EXAMPLE — DELETE ME | I16: =IF($B16="",0,IF(COUNTIF('SEASON VISION'!$B$15:$B$38,$B16)>1,1,0))
B17: VN-003 | C17: One afternoon with nothing in it at all | D17: Last year there was not one | E17: Both | F17: No | H17: EXAMPLE — DELETE ME | I17: =IF($B17="",0,IF(COUNTIF('SEASON VISION'!$B$15:$B$38,$B17)>1,1,0))
I18: =IF($B18="",0,IF(COUNTIF('SEASON VISION'!$B$15:$B$38,$B18)>1,1,0))
I19: =IF($B19="",0,IF(COUNTIF('SEASON VISION'!$B$15:$B$38,$B19)>1,1,0))
I20: =IF($B20="",0,IF(COUNTIF('SEASON VISION'!$B$15:$B$38,$B20)>1,1,0))
I21: =IF($B21="",0,IF(COUNTIF('SEASON VISION'!$B$15:$B$38,$B21)>1,1,0))
I22: =IF($B22="",0,IF(COUNTIF('SEASON VISION'!$B$15:$B$38,$B22)>1,1,0))
I23: =IF($B23="",0,IF(COUNTIF('SEASON VISION'!$B$15:$B$38,$B23)>1,1,0))
I24: =IF($B24="",0,IF(COUNTIF('SEASON VISION'!$B$15:$B$38,$B24)>1,1,0))
I25: =IF($B25="",0,IF(COUNTIF('SEASON VISION'!$B$15:$B$38,$B25)>1,1,0))
I26: =IF($B26="",0,IF(COUNTIF('SEASON VISION'!$B$15:$B$38,$B26)>1,1,0))
I27: =IF($B27="",0,IF(COUNTIF('SEASON VISION'!$B$15:$B$38,$B27)>1,1,0))
I28: =IF($B28="",0,IF(COUNTIF('SEASON VISION'!$B$15:$B$38,$B28)>1,1,0))
I29: =IF($B29="",0,IF(COUNTIF('SEASON VISION'!$B$15:$B$38,$B29)>1,1,0))
... I38: =IF($B38="",0,IF(COUNTIF('SEASON VISION'!$B$15:$B$38,$B38)>1,1,0))

Sheet RECIPIENT PROFILES
B1: Dashboard | D1: Start here | E1: Calendar | F1: Budget | G1: All sheets
B2: RECIPIENT PROFILES
B3: What you know about the people you are giving to, so a gift never has to be guessed at twice.
B4: Cream cells are yours to fill in · pale green cells calculate themselves · amber rows are examples you can delete
B5: Person ID | C5: Name | D5: Relationship | E5: Birthday | F5: Sizes | G5: Preferred colours | H5: Interests | I5: Dislikes | J5: Sensitivities / allergies | K5: Favourite makers | L5: Monogram / engraving | M5: Preferred charities | N5: Address status | O5: Given before | P5: Do not repeat | Q5: Where it is hidden | R5: Notes | S5: QA · duplicate ID
B6: P-001 | C6: Eleanor Whitmore | D6: Parent | F6: Cashmere M · glove 7 | G6: Camel, ivory, deep green | H6: Gardening, Elgar, letter writing | I6: Anything battery powered | J6: Wool next to skin | K6: Smythson, Crabtree | L6: E.M.W. | N6: Confirmed | O6: 2024 silk scarf · 2023 secateurs | P6: Scented candles | Q6: Cedar chest, guest room | R6: EXAMPLE — DELETE ME | S6: =IF($B6="",0,IF(COUNTIF('RECIPIENT PROFILES'!$B$6:$B$105,$B6)>1,1,0))
B7: P-002 | C7: James Whitmore | D7: Spouse or partner | F7: Shirt 16 · shoe 10 | G7: Navy, oxblood | H7: Sailing, single malt, Ordnance Survey maps | I7: Novelty anything | K7: Barbour, Dents | L7: J.A.W. | N7: Confirmed | O7: 2024 chart of the Solent | P7: Ties | Q7: Top of the linen cupboard | R7: EXAMPLE — DELETE ME | S7: =IF($B7="",0,IF(COUNTIF('RECIPIENT PROFILES'!$B$6:$B$105,$B7)>1,1,0))
B8: P-003 | C8: Sofia Lindqvist | D8: Friend | G8: Ink blue | H8: Ceramics, cold-water swimming | J8: Nut allergy — serious | M8: Local river trust | N8: Needs checking | R8: EXAMPLE — DELETE ME | S8: =IF($B8="",0,IF(COUNTIF('RECIPIENT PROFILES'!$B$6:$B$105,$B8)>1,1,0))
S9: =IF($B9="",0,IF(COUNTIF('RECIPIENT PROFILES'!$B$6:$B$105,$B9)>1,1,0))
S10: =IF($B10="",0,IF(COUNTIF('RECIPIENT PROFILES'!$B$6:$B$105,$B10)>1,1,0))
S11: =IF($B11="",0,IF(COUNTIF('RECIPIENT PROFILES'!$B$6:$B$105,$B11)>1,1,0))
S12: =IF($B12="",0,IF(COUNTIF('RECIPIENT PROFILES'!$B$6:$B$105,$B12)>1,1,0))
S13: =IF($B13="",0,IF(COUNTIF('RECIPIENT PROFILES'!$B$6:$B$105,$B13)>1,1,0))
S14: =IF($B14="",0,IF(COUNTIF('RECIPIENT PROFILES'!$B$6:$B$105,$B14)>1,1,0))
S15: =IF($B15="",0,IF(COUNTIF('RECIPIENT PROFILES'!$B$6:$B$105,$B15)>1,1,0))
S16: =IF($B16="",0,IF(COUNTIF('RECIPIENT PROFILES'!$B$6:$B$105,$B16)>1,1,0))
S17: =IF($B17="",0,IF(COUNTIF('RECIPIENT PROFILES'!$B$6:$B$105,$B17)>1,1,0))
S18: =IF($B18="",0,IF(COUNTIF('RECIPIENT PROFILES'!$B$6:$B$105,$B18)>1,1,0))
S19: =IF($B19="",0,IF(COUNTIF('RECIPIENT PROFILES'!$B$6:$B$105,$B19)>1,1,0))
S20: =IF($B20="",0,IF(COUNTIF('RECIPIENT PROFILES'!$B$6:$B$105,$B20)>1,1,0))
... S105: =IF($B105="",0,IF(COUNTIF('RECIPIENT PROFILES'!$B$6:$B$105,$B105)>1,1,0))
B108: Keep only what helps you give well. Do not store payment card numbers, government ID numbers, passwords, or anything you would not want in a spreadsheet.

Sheet PEOPLE + BUDGETS
B1: Dashboard | D1: Start here | E1: Calendar | F1: Budget | G1: All sheets
B2: PEOPLE + BUDGETS
B3: Who you are giving to this year, and what you intend to spend on each of them.
B4: Cream cells are yours to fill in · pale green cells calculate themselves · amber rows are examples you can delete
B5: Person ID | C5: Name | D5: Group | E5: Gift budget | F5: Stocking budget | G5: Total budget | H5: Gifts planned | I5: Gifts actual | J5: Stockings planned | K5: Stockings actual | L5: Spent so far | M5: Remaining | N5: Status | O5: Active? | P5: Notes | Q5: QA · duplicate ID
B6: P-001 | C6: Eleanor Whitmore | D6: Immediate family | E6: 400 | F6: 60 | G6: =IF($B6="","",$E6+$F6) | H6: =IF($B6="","",SUMIFS('GIFT PLANNER'!$Q$6:$Q$205,'GIFT PLANNER'!$C$6:$C$205,$B6,'GIFT PLANNER'!$E$6:$E$205,"Yes")) | I6: =IF($B6="","",SUMIFS('GIFT PLANNER'!$R$6:$R$205,'GIFT PLANNER'!$C$6:$C$205,$B6,'GIFT PLANNER'!$E$6:$E$205,"Yes")) | J6: =IF($B6="","",SUMIFS('STOCKING STUFFERS'!$J$6:$J$155,'STOCKING STUFFERS'!$C$6:$C$155,$B6)) | K6: =IF($B6="","",SUMIFS('STOCKING STUFFERS'!$K$6:$K$155,'STOCKING STUFFERS'!$C$6:$C$155,$B6)) | L6: =IF($B6="","",$I6+$K6) | M6: =IF($B6="","",$G6-$L6) | N6: =IF($B6="","",IF(AND($G6=0,$L6=0),"NOT SET",IF($L6>$G6,"OVER BUDGET",IF($L6=$G6,"AT BUDGET",IF(AND($G6>0,$L6/$G6>=Set_WarnThreshold),"NEAR LIMIT","ON TRACK"))))) | O6: Yes | P6: EXAMPLE — DELETE ME | Q6: =IF($B6="",0,IF(COUNTIF('PEOPLE + BUDGETS'!$B$6:$B$105,$B6)>1,1,0))
B7: P-002 | C7: James Whitmore | D7: Immediate family | E7: 500 | F7: 60 | G7: =IF($B7="","",$E7+$F7) | H7: =IF($B7="","",SUMIFS('GIFT PLANNER'!$Q$6:$Q$205,'GIFT PLANNER'!$C$6:$C$205,$B7,'GIFT PLANNER'!$E$6:$E$205,"Yes")) | I7: =IF($B7="","",SUMIFS('GIFT PLANNER'!$R$6:$R$205,'GIFT PLANNER'!$C$6:$C$205,$B7,'GIFT PLANNER'!$E$6:$E$205,"Yes")) | J7: =IF($B7="","",SUMIFS('STOCKING STUFFERS'!$J$6:$J$155,'STOCKING STUFFERS'!$C$6:$C$155,$B7)) | K7: =IF($B7="","",SUMIFS('STOCKING STUFFERS'!$K$6:$K$155,'STOCKING STUFFERS'!$C$6:$C$155,$B7)) | L7: =IF($B7="","",$I7+$K7) | M7: =IF($B7="","",$G7-$L7) | N7: =IF($B7="","",IF(AND($G7=0,$L7=0),"NOT SET",IF($L7>$G7,"OVER BUDGET",IF($L7=$G7,"AT BUDGET",IF(AND($G7>0,$L7/$G7>=Set_WarnThreshold),"NEAR LIMIT","ON TRACK"))))) | O7: Yes | P7: EXAMPLE — DELETE ME | Q7: =IF($B7="",0,IF(COUNTIF('PEOPLE + BUDGETS'!$B$6:$B$105,$B7)>1,1,0))
B8: P-003 | C8: Sofia Lindqvist | D8: Friends | E8: 120 | F8: 0 | G8: =IF($B8="","",$E8+$F8) | H8: =IF($B8="","",SUMIFS('GIFT PLANNER'!$Q$6:$Q$205,'GIFT PLANNER'!$C$6:$C$205,$B8,'GIFT PLANNER'!$E$6:$E$205,"Yes")) | I8: =IF($B8="","",SUMIFS('GIFT PLANNER'!$R$6:$R$205,'GIFT PLANNER'!$C$6:$C$205,$B8,'GIFT PLANNER'!$E$6:$E$205,"Yes")) | J8: =IF($B8="","",SUMIFS('STOCKING STUFFERS'!$J$6:$J$155,'STOCKING STUFFERS'!$C$6:$C$155,$B8)) | K8: =IF($B8="","",SUMIFS('STOCKING STUFFERS'!$K$6:$K$155,'STOCKING STUFFERS'!$C$6:$C$155,$B8)) | L8: =IF($B8="","",$I8+$K8) | M8: =IF($B8="","",$G8-$L8) | N8: =IF($B8="","",IF(AND($G8=0,$L8=0),"NOT SET",IF($L8>$G8,"OVER BUDGET",IF($L8=$G8,"AT BUDGET",IF(AND($G8>0,$L8/$G8>=Set_WarnThreshold),"NEAR LIMIT","ON TRACK"))))) | O8: Yes | P8: EXAMPLE — DELETE ME | Q8: =IF($B8="",0,IF(COUNTIF('PEOPLE + BUDGETS'!$B$6:$B$105,$B8)>1,1,0))
G9: =IF($B9="","",$E9+$F9) | H9: =IF($B9="","",SUMIFS('GIFT PLANNER'!$Q$6:$Q$205,'GIFT PLANNER'!$C$6:$C$205,$B9,'GIFT PLANNER'!$E$6:$E$205,"Yes")) | I9: =IF($B9="","",SUMIFS('GIFT PLANNER'!$R$6:$R$205,'GIFT PLANNER'!$C$6:$C$205,$B9,'GIFT PLANNER'!$E$6:$E$205,"Yes")) | J9: =IF($B9="","",SUMIFS('STOCKING STUFFERS'!$J$6:$J$155,'STOCKING STUFFERS'!$C$6:$C$155,$B9)) | K9: =IF($B9="","",SUMIFS('STOCKING STUFFERS'!$K$6:$K$155,'STOCKING STUFFERS'!$C$6:$C$155,$B9)) | L9: =IF($B9="","",$I9+$K9) | M9: =IF($B9="","",$G9-$L9) | N9: =IF($B9="","",IF(AND($G9=0,$L9=0),"NOT SET",IF($L9>$G9,"OVER BUDGET",IF($L9=$G9,"AT BUDGET",IF(AND($G9>0,$L9/$G9>=Set_WarnThreshold),"NEAR LIMIT","ON TRACK"))))) | Q9: =IF($B9="",0,IF(COUNTIF('PEOPLE + BUDGETS'!$B$6:$B$105,$B9)>1,1,0))
G10: =IF($B10="","",$E10+$F10) | H10: =IF($B10="","",SUMIFS('GIFT PLANNER'!$Q$6:$Q$205,'GIFT PLANNER'!$C$6:$C$205,$B10,'GIFT PLANNER'!$E$6:$E$205,"Yes")) | I10: =IF($B10="","",SUMIFS('GIFT PLANNER'!$R$6:$R$205,'GIFT PLANNER'!$C$6:$C$205,$B10,'GIFT PLANNER'!$E$6:$E$205,"Yes")) | J10: =IF($B10="","",SUMIFS('STOCKING STUFFERS'!$J$6:$J$155,'STOCKING STUFFERS'!$C$6:$C$155,$B10)) | K10: =IF($B10="","",SUMIFS('STOCKING STUFFERS'!$K$6:$K$155,'STOCKING STUFFERS'!$C$6:$C$155,$B10)) | L10: =IF($B10="","",$I10+$K10) | M10: =IF($B10="","",$G10-$L10) | N10: =IF($B10="","",IF(AND($G10=0,$L10=0),"NOT SET",IF($L10>$G10,"OVER BUDGET",IF($L10=$G10,"AT BUDGET",IF(AND($G10>0,$L10/$G10>=Set_WarnThreshold),"NEAR LIMIT","ON TRACK"))))) | Q10: =IF($B10="",0,IF(COUNTIF('PEOPLE + BUDGETS'!$B$6:$B$105,$B10)>1,1,0))
G11: =IF($B11="","",$E11+$F11) | H11: =IF($B11="","",SUMIFS('GIFT PLANNER'!$Q$6:$Q$205,'GIFT PLANNER'!$C$6:$C$205,$B11,'GIFT PLANNER'!$E$6:$E$205,"Yes")) | I11: =IF($B11="","",SUMIFS('GIFT PLANNER'!$R$6:$R$205,'GIFT PLANNER'!$C$6:$C$205,$B11,'GIFT PLANNER'!$E$6:$E$205,"Yes")) | J11: =IF($B11="","",SUMIFS('STOCKING STUFFERS'!$J$6:$J$155,'STOCKING STUFFERS'!$C$6:$C$155,$B11)) | K11: =IF($B11="","",SUMIFS('STOCKING STUFFERS'!$K$6:$K$155,'STOCKING STUFFERS'!$C$6:$C$155,$B11)) | L11: =IF($B11="","",$I11+$K11) | M11: =IF($B11="","",$G11-$L11) | N11: =IF($B11="","",IF(AND($G11=0,$L11=0),"NOT SET",IF($L11>$G11,"OVER BUDGET",IF($L11=$G11,"AT BUDGET",IF(AND($G11>0,$L11/$G11>=Set_WarnThreshold),"NEAR LIMIT","ON TRACK"))))) | Q11: =IF($B11="",0,IF(COUNTIF('PEOPLE + BUDGETS'!$B$6:$B$105,$B11)>1,1,0))
G12: =IF($B12="","",$E12+$F12) | H12: =IF($B12="","",SUMIFS('GIFT PLANNER'!$Q$6:$Q$205,'GIFT PLANNER'!$C$6:$C$205,$B12,'GIFT PLANNER'!$E$6:$E$205,"Yes")) | I12: =IF($B12="","",SUMIFS('GIFT PLANNER'!$R$6:$R$205,'GIFT PLANNER'!$C$6:$C$205,$B12,'GIFT PLANNER'!$E$6:$E$205,"Yes")) | J12: =IF($B12="","",SUMIFS('STOCKING STUFFERS'!$J$6:$J$155,'STOCKING STUFFERS'!$C$6:$C$155,$B12)) | K12: =IF($B12="","",SUMIFS('STOCKING STUFFERS'!$K$6:$K$155,'STOCKING STUFFERS'!$C$6:$C$155,$B12)) | L12: =IF($B12="","",$I12+$K12) | M12: =IF($B12="","",$G12-$L12) | N12: =IF($B12="","",IF(AND($G12=0,$L12=0),"NOT SET",IF($L12>$G12,"OVER BUDGET",IF($L12=$G12,"AT BUDGET",IF(AND($G12>0,$L12/$G12>=Set_WarnThreshold),"NEAR LIMIT","ON TRACK"))))) | Q12: =IF($B12="",0,IF(COUNTIF('PEOPLE + BUDGETS'!$B$6:$B$105,$B12)>1,1,0))
G13: =IF($B13="","",$E13+$F13) | H13: =IF($B13="","",SUMIFS('GIFT PLANNER'!$Q$6:$Q$205,'GIFT PLANNER'!$C$6:$C$205,$B13,'GIFT PLANNER'!$E$6:$E$205,"Yes")) | I13: =IF($B13="","",SUMIFS('GIFT PLANNER'!$R$6:$R$205,'GIFT PLANNER'!$C$6:$C$205,$B13,'GIFT PLANNER'!$E$6:$E$205,"Yes")) | J13: =IF($B13="","",SUMIFS('STOCKING STUFFERS'!$J$6:$J$155,'STOCKING STUFFERS'!$C$6:$C$155,$B13)) | K13: =IF($B13="","",SUMIFS('STOCKING STUFFERS'!$K$6:$K$155,'STOCKING STUFFERS'!$C$6:$C$155,$B13)) | L13: =IF($B13="","",$I13+$K13) | M13: =IF($B13="","",$G13-$L13) | N13: =IF($B13="","",IF(AND($G13=0,$L13=0),"NOT SET",IF($L13>$G13,"OVER BUDGET",IF($L13=$G13,"AT BUDGET",IF(AND($G13>0,$L13/$G13>=Set_WarnThreshold),"NEAR LIMIT","ON TRACK"))))) | Q13: =IF($B13="",0,IF(COUNTIF('PEOPLE + BUDGETS'!$B$6:$B$105,$B13)>1,1,0))
G14: =IF($B14="","",$E14+$F14) | H14: =IF($B14="","",SUMIFS('GIFT PLANNER'!$Q$6:$Q$205,'GIFT PLANNER'!$C$6:$C$205,$B14,'GIFT PLANNER'!$E$6:$E$205,"Yes")) | I14: =IF($B14="","",SUMIFS('GIFT PLANNER'!$R$6:$R$205,'GIFT PLANNER'!$C$6:$C$205,$B14,'GIFT PLANNER'!$E$6:$E$205,"Yes")) | J14: =IF($B14="","",SUMIFS('STOCKING STUFFERS'!$J$6:$J$155,'STOCKING STUFFERS'!$C$6:$C$155,$B14)) | K14: =IF($B14="","",SUMIFS('STOCKING STUFFERS'!$K$6:$K$155,'STOCKING STUFFERS'!$C$6:$C$155,$B14)) | L14: =IF($B14="","",$I14+$K14) | M14: =IF($B14="","",$G14-$L14) | N14: =IF($B14="","",IF(AND($G14=0,$L14=0),"NOT SET",IF($L14>$G14,"OVER BUDGET",IF($L14=$G14,"AT BUDGET",IF(AND($G14>0,$L14/$G14>=Set_WarnThreshold),"NEAR LIMIT","ON TRACK"))))) | Q14: =IF($B14="",0,IF(COUNTIF('PEOPLE + BUDGETS'!$B$6:$B$105,$B14)>1,1,0))
G15: =IF($B15="","",$E15+$F15) | H15: =IF($B15="","",SUMIFS('GIFT PLANNER'!$Q$6:$Q$205,'GIFT PLANNER'!$C$6:$C$205,$B15,'GIFT PLANNER'!$E$6:$E$205,"Yes")) | I15: =IF($B15="","",SUMIFS('GIFT PLANNER'!$R$6:$R$205,'GIFT PLANNER'!$C$6:$C$205,$B15,'GIFT PLANNER'!$E$6:$E$205,"Yes")) | J15: =IF($B15="","",SUMIFS('STOCKING STUFFERS'!$J$6:$J$155,'STOCKING STUFFERS'!$C$6:$C$155,$B15)) | K15: =IF($B15="","",SUMIFS('STOCKING STUFFERS'!$K$6:$K$155,'STOCKING STUFFERS'!$C$6:$C$155,$B15)) | L15: =IF($B15="","",$I15+$K15) | M15: =IF($B15="","",$G15-$L15) | N15: =IF($B15="","",IF(AND($G15=0,$L15=0),"NOT SET",IF($L15>$G15,"OVER BUDGET",IF($L15=$G15,"AT BUDGET",IF(AND($G15>0,$L15/$G15>=Set_WarnThreshold),"NEAR LIMIT","ON TRACK"))))) | Q15: =IF($B15="",0,IF(COUNTIF('PEOPLE + BUDGETS'!$B$6:$B$105,$B15)>1,1,0))
G16: =IF($B16="","",$E16+$F16) | H16: =IF($B16="","",SUMIFS('GIFT PLANNER'!$Q$6:$Q$205,'GIFT PLANNER'!$C$6:$C$205,$B16,'GIFT PLANNER'!$E$6:$E$205,"Yes")) | I16: =IF($B16="","",SUMIFS('GIFT PLANNER'!$R$6:$R$205,'GIFT PLANNER'!$C$6:$C$205,$B16,'GIFT PLANNER'!$E$6:$E$205,"Yes")) | J16: =IF($B16="","",SUMIFS('STOCKING STUFFERS'!$J$6:$J$155,'STOCKING STUFFERS'!$C$6:$C$155,$B16)) | K16: =IF($B16="","",SUMIFS('STOCKING STUFFERS'!$K$6:$K$155,'STOCKING STUFFERS'!$C$6:$C$155,$B16)) | L16: =IF($B16="","",$I16+$K16) | M16: =IF($B16="","",$G16-$L16) | N16: =IF($B16="","",IF(AND($G16=0,$L16=0),"NOT SET",IF($L16>$G16,"OVER BUDGET",IF($L16=$G16,"AT BUDGET",IF(AND($G16>0,$L16/$G16>=Set_WarnThreshold),"NEAR LIMIT","ON TRACK"))))) | Q16: =IF($B16="",0,IF(COUNTIF('PEOPLE + BUDGETS'!$B$6:$B$105,$B16)>1,1,0))
G17: =IF($B17="","",$E17+$F17) | H17: =IF($B17="","",SUMIFS('GIFT PLANNER'!$Q$6:$Q$205,'GIFT PLANNER'!$C$6:$C$205,$B17,'GIFT PLANNER'!$E$6:$E$205,"Yes")) | I17: =IF($B17="","",SUMIFS('GIFT PLANNER'!$R$6:$R$205,'GIFT PLANNER'!$C$6:$C$205,$B17,'GIFT PLANNER'!$E$6:$E$205,"Yes")) | J17: =IF($B17="","",SUMIFS('STOCKING STUFFERS'!$J$6:$J$155,'STOCKING STUFFERS'!$C$6:$C$155,$B17)) | K17: =IF($B17="","",SUMIFS('STOCKING STUFFERS'!$K$6:$K$155,'STOCKING STUFFERS'!$C$6:$C$155,$B17)) | L17: =IF($B17="","",$I17+$K17) | M17: =IF($B17="","",$G17-$L17) | N17: =IF($B17="","",IF(AND($G17=0,$L17=0),"NOT SET",IF($L17>$G17,"OVER BUDGET",IF($L17=$G17,"AT BUDGET",IF(AND($G17>0,$L17/$G17>=Set_WarnThreshold),"NEAR LIMIT","ON TRACK"))))) | Q17: =IF($B17="",0,IF(COUNTIF('PEOPLE + BUDGETS'!$B$6:$B$105,$B17)>1,1,0))
G18: =IF($B18="","",$E18+$F18) | H18: =IF($B18="","",SUMIFS('GIFT PLANNER'!$Q$6:$Q$205,'GIFT PLANNER'!$C$6:$C$205,$B18,'GIFT PLANNER'!$E$6:$E$205,"Yes")) | I18: =IF($B18="","",SUMIFS('GIFT PLANNER'!$R$6:$R$205,'GIFT PLANNER'!$C$6:$C$205,$B18,'GIFT PLANNER'!$E$6:$E$205,"Yes")) | J18: =IF($B18="","",SUMIFS('STOCKING STUFFERS'!$J$6:$J$155,'STOCKING STUFFERS'!$C$6:$C$155,$B18)) | K18: =IF($B18="","",SUMIFS('STOCKING STUFFERS'!$K$6:$K$155,'STOCKING STUFFERS'!$C$6:$C$155,$B18)) | L18: =IF($B18="","",$I18+$K18) | M18: =IF($B18="","",$G18-$L18) | N18: =IF($B18="","",IF(AND($G18=0,$L18=0),"NOT SET",IF($L18>$G18,"OVER BUDGET",IF($L18=$G18,"AT BUDGET",IF(AND($G18>0,$L18/$G18>=Set_WarnThreshold),"NEAR LIMIT","ON TRACK"))))) | Q18: =IF($B18="",0,IF(COUNTIF('PEOPLE + BUDGETS'!$B$6:$B$105,$B18)>1,1,0))
G19: =IF($B19="","",$E19+$F19) | H19: =IF($B19="","",SUMIFS('GIFT PLANNER'!$Q$6:$Q$205,'GIFT PLANNER'!$C$6:$C$205,$B19,'GIFT PLANNER'!$E$6:$E$205,"Yes")) | I19: =IF($B19="","",SUMIFS('GIFT PLANNER'!$R$6:$R$205,'GIFT PLANNER'!$C$6:$C$205,$B19,'GIFT PLANNER'!$E$6:$E$205,"Yes")) | J19: =IF($B19="","",SUMIFS('STOCKING STUFFERS'!$J$6:$J$155,'STOCKING STUFFERS'!$C$6:$C$155,$B19)) | K19: =IF($B19="","",SUMIFS('STOCKING STUFFERS'!$K$6:$K$155,'STOCKING STUFFERS'!$C$6:$C$155,$B19)) | L19: =IF($B19="","",$I19+$K19) | M19: =IF($B19="","",$G19-$L19) | N19: =IF($B19="","",IF(AND($G19=0,$L19=0),"NOT SET",IF($L19>$G19,"OVER BUDGET",IF($L19=$G19,"AT BUDGET",IF(AND($G19>0,$L19/$G19>=Set_WarnThreshold),"NEAR LIMIT","ON TRACK"))))) | Q19: =IF($B19="",0,IF(COUNTIF('PEOPLE + BUDGETS'!$B$6:$B$105,$B19)>1,1,0))
G20: =IF($B20="","",$E20+$F20) | H20: =IF($B20="","",SUMIFS('GIFT PLANNER'!$Q$6:$Q$205,'GIFT PLANNER'!$C$6:$C$205,$B20,'GIFT PLANNER'!$E$6:$E$205,"Yes")) | I20: =IF($B20="","",SUMIFS('GIFT PLANNER'!$R$6:$R$205,'GIFT PLANNER'!$C$6:$C$205,$B20,'GIFT PLANNER'!$E$6:$E$205,"Yes")) | J20: =IF($B20="","",SUMIFS('STOCKING STUFFERS'!$J$6:$J$155,'STOCKING STUFFERS'!$C$6:$C$155,$B20)) | K20: =IF($B20="","",SUMIFS('STOCKING STUFFERS'!$K$6:$K$155,'STOCKING STUFFERS'!$C$6:$C$155,$B20)) | L20: =IF($B20="","",$I20+$K20) | M20: =IF($B20="","",$G20-$L20) | N20: =IF($B20="","",IF(AND($G20=0,$L20=0),"NOT SET",IF($L20>$G20,"OVER BUDGET",IF($L20=$G20,"AT BUDGET",IF(AND($G20>0,$L20/$G20>=Set_WarnThreshold),"NEAR LIMIT","ON TRACK"))))) | Q20: =IF($B20="",0,IF(COUNTIF('PEOPLE + BUDGETS'!$B$6:$B$105,$B20)>1,1,0))
... G105: =IF($B105="","",$E105+$F105) | H105: =IF($B105="","",SUMIFS('GIFT PLANNER'!$Q$6:$Q$205,'GIFT PLANNER'!$C$6:$C$205,$B105,'GIFT PLANNER'!$E$6:$E$205,"Yes")) | I105: =IF($B105="","",SUMIFS('GIFT PLANNER'!$R$6:$R$205,'GIFT PLANNER'!$C$6:$C$205,$B105,'GIFT PLANNER'!$E$6:$E$205,"Yes")) | J105: =IF($B105="","",SUMIFS('STOCKING STUFFERS'!$J$6:$J$155,'STOCKING STUFFERS'!$C$6:$C$155,$B105)) | K105: =IF($B105="","",SUMIFS('STOCKING STUFFERS'!$K$6:$K$155,'STOCKING STUFFERS'!$C$6:$C$155,$B105)) | L105: =IF($B105="","",$I105+$K105) | M105: =IF($B105="","",$G105-$L105) | N105: =IF($B105="","",IF(AND($G105=0,$L105=0),"NOT SET",IF($L105>$G105,"OVER BUDGET",IF($L105=$G105,"AT BUDGET",IF(AND($G105>0,$L105/$G105>=Set_WarnThreshold),"NEAR LIMIT","ON TRACK"))))) | Q105: =IF($B105="",0,IF(COUNTIF('PEOPLE + BUDGETS'!$B$6:$B$105,$B105)>1,1,0))

Sheet MASTER BUDGET
B1: Dashboard | D1: Start here | E1: Calendar | F1: Budget | G1: All sheets
B2: MASTER BUDGET
B3: What you set aside, what is planned against it, and what has actually left your account.
B4: Cream cells are yours to fill in · pale green cells calculate themselves · amber rows are examples you can delete
B5: Category ID | C5: In use? | D5: Category | E5: Budget | F5: Planned | G5: Actual | H5: Remaining | I5: Used | J5: Status | K5: Notes | L5: Chart rank key | M5: QA · duplicate ID
B6: B-001 | C6: Yes | D6: Gifts | E6: 2400 | F6: =IF($D6="","",SUMIFS('CARDS + MAIL'!$I$6:$I$155,'CARDS + MAIL'!$H$6:$H$155,$D6)+SUMIFS('DONATIONS + GIVING'!$G$6:$G$65,'DONATIONS + GIVING'!$F$6:$F$65,$D6)+SUMIFS('GIFT PLANNER'!$Q$6:$Q$205,'GIFT PLANNER'!$G$6:$G$205,$D6)+SUMIFS('STOCKING STUFFERS'!$J$6:$J$155,'STOCKING STUFFERS'!$F$6:$F$155,$D6)+SUMIFS('CHRISTMAS CALENDAR'!$K$6:$K$205,'CHRISTMAS CALENDAR'!$J$6:$J$205,$D6)+SUMIFS('DECOR INVENTORY'!$P$6:$P$105,'DECOR INVENTORY'!$O$6:$O$105,$D6)+SUMIFS('DECORATING PLAN'!$H$6:$H$65,'DECORATING PLAN'!$G$6:$G$65,$D6)+SUMIFS('TABLESCAPE + FLORALS'!$R$6:$R$65,'TABLESCAPE + FLORALS'!$Q$6:$Q$65,$D6)+SUMIFS('TRAVEL PLAN'!$M$6:$M$45,'TRAVEL PLAN'!$L$6:$L$45,$D6)+SUMIFS('VENDORS + APPOINTMENTS'!$M$6:$M$65,'VENDORS + APPOINTMENTS'!$L$6:$L$65,$D6)+SUMIFS('EVENTS + WARDROBE'!$N$6:$N$65,'EVENTS + WARDROBE'!$M$6:$M$65,$D6)+SUMIFS('GROCERY LIST'!$L$6:$L$205,'GROCERY LIST'!$K$6:$K$205,$D6)+SUMIFS('MEAL + BAKING PLAN'!$Q$6:$Q$155,'MEAL + BAKING PLAN'!$P$6:$P$155,$D6)+SUMIFS('TRADITIONS + BUCKET LIST'!$I$6:$I$85,'TRADITIONS + BUCKET LIST'!$H$6:$H$85,$D6)) | G6: =IF($D6="","",SUMIFS('CARDS + MAIL'!$J$6:$J$155,'CARDS + MAIL'!$H$6:$H$155,$D6)+SUMIFS('DONATIONS + GIVING'!$H$6:$H$65,'DONATIONS + GIVING'!$F$6:$F$65,$D6)+SUMIFS('GIFT PLANNER'!$R$6:$R$205,'GIFT PLANNER'!$G$6:$G$205,$D6)+SUMIFS('STOCKING STUFFERS'!$K$6:$K$155,'STOCKING STUFFERS'!$F$6:$F$155,$D6)+SUMIFS('CHRISTMAS CALENDAR'!$L$6:$L$205,'CHRISTMAS CALENDAR'!$J$6:$J$205,$D6)+SUMIFS('DECOR INVENTORY'!$Q$6:$Q$105,'DECOR INVENTORY'!$O$6:$O$105,$D6)+SUMIFS('DECORATING PLAN'!$I$6:$I$65,'DECORATING PLAN'!$G$6:$G$65,$D6)+SUMIFS('TABLESCAPE + FLORALS'!$S$6:$S$65,'TABLESCAPE + FLORALS'!$Q$6:$Q$65,$D6)+SUMIFS('TRAVEL PLAN'!$N$6:$N$45,'TRAVEL PLAN'!$L$6:$L$45,$D6)+SUMIFS('VENDORS + APPOINTMENTS'!$Q$6:$Q$65,'VENDORS + APPOINTMENTS'!$L$6:$L$65,$D6)+SUMIFS('EVENTS + WARDROBE'!$O$6:$O$65,'EVENTS + WARDROBE'!$M$6:$M$65,$D6)+SUMIFS('GROCERY LIST'!$M$6:$M$205,'GROCERY LIST'!$K$6:$K$205,$D6)+SUMIFS('MEAL + BAKING PLAN'!$R$6:$R$155,'MEAL + BAKING PLAN'!$P$6:$P$155,$D6)+SUMIFS('TRADITIONS + BUCKET LIST'!$J$6:$J$85,'TRADITIONS + BUCKET LIST'!$H$6:$H$85,$D6)-SUMIFS('RETURNS + EXCHANGES'!$R$6:$R$65,'RETURNS + EXCHANGES'!$K$6:$K$65,$D6)) | H6: =IF($D6="","",$E6-$G6) | I6: =IF($D6="","",IF($E6=0,0,$G6/$E6)) | J6: =IF($D6="","",IF(AND($E6=0,$G6=0),"NOT SET",IF($G6>$E6,"OVER BUDGET",IF($G6=$E6,"AT BUDGET",IF(AND($E6>0,$G6/$E6>=Set_WarnThreshold),"NEAR LIMIT","ON TRACK"))))) | K6: EXAMPLE FIGURE — type your own over it | L6: =IF(AND($C6="Yes",$D6<>"",OR(N($E6)>0,N($G6)>0)),$E6+(100-ROW())/10000,"") | M6: =IF($B6="",0,IF(COUNTIF('MASTER BUDGET'!$B$6:$B$25,$B6)>1,1,0))
B7: B-002 | C7: Yes | D7: Stockings | E7: 300 | F7: =IF($D7="","",SUMIFS('CARDS + MAIL'!$I$6:$I$155,'CARDS + MAIL'!$H$6:$H$155,$D7)+SUMIFS('DONATIONS + GIVING'!$G$6:$G$65,'DONATIONS + GIVING'!$F$6:$F$65,$D7)+SUMIFS('GIFT PLANNER'!$Q$6:$Q$205,'GIFT PLANNER'!$G$6:$G$205,$D7)+SUMIFS('STOCKING STUFFERS'!$J$6:$J$155,'STOCKING STUFFERS'!$F$6:$F$155,$D7)+SUMIFS('CHRISTMAS CALENDAR'!$K$6:$K$205,'CHRISTMAS CALENDAR'!$J$6:$J$205,$D7)+SUMIFS('DECOR INVENTORY'!$P$6:$P$105,'DECOR INVENTORY'!$O$6:$O$105,$D7)+SUMIFS('DECORATING PLAN'!$H$6:$H$65,'DECORATING PLAN'!$G$6:$G$65,$D7)+SUMIFS('TABLESCAPE + FLORALS'!$R$6:$R$65,'TABLESCAPE + FLORALS'!$Q$6:$Q$65,$D7)+SUMIFS('TRAVEL PLAN'!$M$6:$M$45,'TRAVEL PLAN'!$L$6:$L$45,$D7)+SUMIFS('VENDORS + APPOINTMENTS'!$M$6:$M$65,'VENDORS + APPOINTMENTS'!$L$6:$L$65,$D7)+SUMIFS('EVENTS + WARDROBE'!$N$6:$N$65,'EVENTS + WARDROBE'!$M$6:$M$65,$D7)+SUMIFS('GROCERY LIST'!$L$6:$L$205,'GROCERY LIST'!$K$6:$K$205,$D7)+SUMIFS('MEAL + BAKING PLAN'!$Q$6:$Q$155,'MEAL + BAKING PLAN'!$P$6:$P$155,$D7)+SUMIFS('TRADITIONS + BUCKET LIST'!$I$6:$I$85,'TRADITIONS + BUCKET LIST'!$H$6:$H$85,$D7)) | G7: =IF($D7="","",SUMIFS('CARDS + MAIL'!$J$6:$J$155,'CARDS + MAIL'!$H$6:$H$155,$D7)+SUMIFS('DONATIONS + GIVING'!$H$6:$H$65,'DONATIONS + GIVING'!$F$6:$F$65,$D7)+SUMIFS('GIFT PLANNER'!$R$6:$R$205,'GIFT PLANNER'!$G$6:$G$205,$D7)+SUMIFS('STOCKING STUFFERS'!$K$6:$K$155,'STOCKING STUFFERS'!$F$6:$F$155,$D7)+SUMIFS('CHRISTMAS CALENDAR'!$L$6:$L$205,'CHRISTMAS CALENDAR'!$J$6:$J$205,$D7)+SUMIFS('DECOR INVENTORY'!$Q$6:$Q$105,'DECOR INVENTORY'!$O$6:$O$105,$D7)+SUMIFS('DECORATING PLAN'!$I$6:$I$65,'DECORATING PLAN'!$G$6:$G$65,$D7)+SUMIFS('TABLESCAPE + FLORALS'!$S$6:$S$65,'TABLESCAPE + FLORALS'!$Q$6:$Q$65,$D7)+SUMIFS('TRAVEL PLAN'!$N$6:$N$45,'TRAVEL PLAN'!$L$6:$L$45,$D7)+SUMIFS('VENDORS + APPOINTMENTS'!$Q$6:$Q$65,'VENDORS + APPOINTMENTS'!$L$6:$L$65,$D7)+SUMIFS('EVENTS + WARDROBE'!$O$6:$O$65,'EVENTS + WARDROBE'!$M$6:$M$65,$D7)+SUMIFS('GROCERY LIST'!$M$6:$M$205,'GROCERY LIST'!$K$6:$K$205,$D7)+SUMIFS('MEAL + BAKING PLAN'!$R$6:$R$155,'MEAL + BAKING PLAN'!$P$6:$P$155,$D7)+SUMIFS('TRADITIONS + BUCKET LIST'!$J$6:$J$85,'TRADITIONS + BUCKET LIST'!$H$6:$H$85,$D7)-SUMIFS('RETURNS + EXCHANGES'!$R$6:$R$65,'RETURNS + EXCHANGES'!$K$6:$K$65,$D7)) | H7: =IF($D7="","",$E7-$G7) | I7: =IF($D7="","",IF($E7=0,0,$G7/$E7)) | J7: =IF($D7="","",IF(AND($E7=0,$G7=0),"NOT SET",IF($G7>$E7,"OVER BUDGET",IF($G7=$E7,"AT BUDGET",IF(AND($E7>0,$G7/$E7>=Set_WarnThreshold),"NEAR LIMIT","ON TRACK"))))) | K7: EXAMPLE FIGURE — type your own over it | L7: =IF(AND($C7="Yes",$D7<>"",OR(N($E7)>0,N($G7)>0)),$E7+(100-ROW())/10000,"") | M7: =IF($B7="",0,IF(COUNTIF('MASTER BUDGET'!$B$6:$B$25,$B7)>1,1,0))
B8: B-003 | C8: Yes | D8: Decorations | E8: 600 | F8: =IF($D8="","",SUMIFS('CARDS + MAIL'!$I$6:$I$155,'CARDS + MAIL'!$H$6:$H$155,$D8)+SUMIFS('DONATIONS + GIVING'!$G$6:$G$65,'DONATIONS + GIVING'!$F$6:$F$65,$D8)+SUMIFS('GIFT PLANNER'!$Q$6:$Q$205,'GIFT PLANNER'!$G$6:$G$205,$D8)+SUMIFS('STOCKING STUFFERS'!$J$6:$J$155,'STOCKING STUFFERS'!$F$6:$F$155,$D8)+SUMIFS('CHRISTMAS CALENDAR'!$K$6:$K$205,'CHRISTMAS CALENDAR'!$J$6:$J$205,$D8)+SUMIFS('DECOR INVENTORY'!$P$6:$P$105,'DECOR INVENTORY'!$O$6:$O$105,$D8)+SUMIFS('DECORATING PLAN'!$H$6:$H$65,'DECORATING PLAN'!$G$6:$G$65,$D8)+SUMIFS('TABLESCAPE + FLORALS'!$R$6:$R$65,'TABLESCAPE + FLORALS'!$Q$6:$Q$65,$D8)+SUMIFS('TRAVEL PLAN'!$M$6:$M$45,'TRAVEL PLAN'!$L$6:$L$45,$D8)+SUMIFS('VENDORS + APPOINTMENTS'!$M$6:$M$65,'VENDORS + APPOINTMENTS'!$L$6:$L$65,$D8)+SUMIFS('EVENTS + WARDROBE'!$N$6:$N$65,'EVENTS + WARDROBE'!$M$6:$M$65,$D8)+SUMIFS('GROCERY LIST'!$L$6:$L$205,'GROCERY LIST'!$K$6:$K$205,$D8)+SUMIFS('MEAL + BAKING PLAN'!$Q$6:$Q$155,'MEAL + BAKING PLAN'!$P$6:$P$155,$D8)+SUMIFS('TRADITIONS + BUCKET LIST'!$I$6:$I$85,'TRADITIONS + BUCKET LIST'!$H$6:$H$85,$D8)) | G8: =IF($D8="","",SUMIFS('CARDS + MAIL'!$J$6:$J$155,'CARDS + MAIL'!$H$6:$H$155,$D8)+SUMIFS('DONATIONS + GIVING'!$H$6:$H$65,'DONATIONS + GIVING'!$F$6:$F$65,$D8)+SUMIFS('GIFT PLANNER'!$R$6:$R$205,'GIFT PLANNER'!$G$6:$G$205,$D8)+SUMIFS('STOCKING STUFFERS'!$K$6:$K$155,'STOCKING STUFFERS'!$F$6:$F$155,$D8)+SUMIFS('CHRISTMAS CALENDAR'!$L$6:$L$205,'CHRISTMAS CALENDAR'!$J$6:$J$205,$D8)+SUMIFS('DECOR INVENTORY'!$Q$6:$Q$105,'DECOR INVENTORY'!$O$6:$O$105,$D8)+SUMIFS('DECORATING PLAN'!$I$6:$I$65,'DECORATING PLAN'!$G$6:$G$65,$D8)+SUMIFS('TABLESCAPE + FLORALS'!$S$6:$S$65,'TABLESCAPE + FLORALS'!$Q$6:$Q$65,$D8)+SUMIFS('TRAVEL PLAN'!$N$6:$N$45,'TRAVEL PLAN'!$L$6:$L$45,$D8)+SUMIFS('VENDORS + APPOINTMENTS'!$Q$6:$Q$65,'VENDORS + APPOINTMENTS'!$L$6:$L$65,$D8)+SUMIFS('EVENTS + WARDROBE'!$O$6:$O$65,'EVENTS + WARDROBE'!$M$6:$M$65,$D8)+SUMIFS('GROCERY LIST'!$M$6:$M$205,'GROCERY LIST'!$K$6:$K$205,$D8)+SUMIFS('MEAL + BAKING PLAN'!$R$6:$R$155,'MEAL + BAKING PLAN'!$P$6:$P$155,$D8)+SUMIFS('TRADITIONS + BUCKET LIST'!$J$6:$J$85,'TRADITIONS + BUCKET LIST'!$H$6:$H$85,$D8)-SUMIFS('RETURNS + EXCHANGES'!$R$6:$R$65,'RETURNS + EXCHANGES'!$K$6:$K$65,$D8)) | H8: =IF($D8="","",$E8-$G8) | I8: =IF($D8="","",IF($E8=0,0,$G8/$E8)) | J8: =IF($D8="","",IF(AND($E8=0,$G8=0),"NOT SET",IF($G8>$E8,"OVER BUDGET",IF($G8=$E8,"AT BUDGET",IF(AND($E8>0,$G8/$E8>=Set_WarnThreshold),"NEAR LIMIT","ON TRACK"))))) | K8: EXAMPLE FIGURE — type your own over it | L8: =IF(AND($C8="Yes",$D8<>"",OR(N($E8)>0,N($G8)>0)),$E8+(100-ROW())/10000,"") | M8: =IF($B8="",0,IF(COUNTIF('MASTER BUDGET'!$B$6:$B$25,$B8)>1,1,0))
B9: B-004 | C9: Yes | D9: Food & Baking | E9: 900 | F9: =IF($D9="","",SUMIFS('CARDS + MAIL'!$I$6:$I$155,'CARDS + MAIL'!$H$6:$H$155,$D9)+SUMIFS('DONATIONS + GIVING'!$G$6:$G$65,'DONATIONS + GIVING'!$F$6:$F$65,$D9)+SUMIFS('GIFT PLANNER'!$Q$6:$Q$205,'GIFT PLANNER'!$G$6:$G$205,$D9)+SUMIFS('STOCKING STUFFERS'!$J$6:$J$155,'STOCKING STUFFERS'!$F$6:$F$155,$D9)+SUMIFS('CHRISTMAS CALENDAR'!$K$6:$K$205,'CHRISTMAS CALENDAR'!$J$6:$J$205,$D9)+SUMIFS('DECOR INVENTORY'!$P$6:$P$105,'DECOR INVENTORY'!$O$6:$O$105,$D9)+SUMIFS('DECORATING PLAN'!$H$6:$H$65,'DECORATING PLAN'!$G$6:$G$65,$D9)+SUMIFS('TABLESCAPE + FLORALS'!$R$6:$R$65,'TABLESCAPE + FLORALS'!$Q$6:$Q$65,$D9)+SUMIFS('TRAVEL PLAN'!$M$6:$M$45,'TRAVEL PLAN'!$L$6:$L$45,$D9)+SUMIFS('VENDORS + APPOINTMENTS'!$M$6:$M$65,'VENDORS + APPOINTMENTS'!$L$6:$L$65,$D9)+SUMIFS('EVENTS + WARDROBE'!$N$6:$N$65,'EVENTS + WARDROBE'!$M$6:$M$65,$D9)+SUMIFS('GROCERY LIST'!$L$6:$L$205,'GROCERY LIST'!$K$6:$K$205,$D9)+SUMIFS('MEAL + BAKING PLAN'!$Q$6:$Q$155,'MEAL + BAKING PLAN'!$P$6:$P$155,$D9)+SUMIFS('TRADITIONS + BUCKET LIST'!$I$6:$I$85,'TRADITIONS + BUCKET LIST'!$H$6:$H$85,$D9)) | G9: =IF($D9="","",SUMIFS('CARDS + MAIL'!$J$6:$J$155,'CARDS + MAIL'!$H$6:$H$155,$D9)+SUMIFS('DONATIONS + GIVING'!$H$6:$H$65,'DONATIONS + GIVING'!$F$6:$F$65,$D9)+SUMIFS('GIFT PLANNER'!$R$6:$R$205,'GIFT PLANNER'!$G$6:$G$205,$D9)+SUMIFS('STOCKING STUFFERS'!$K$6:$K$155,'STOCKING STUFFERS'!$F$6:$F$155,$D9)+SUMIFS('CHRISTMAS CALENDAR'!$L$6:$L$205,'CHRISTMAS CALENDAR'!$J$6:$J$205,$D9)+SUMIFS('DECOR INVENTORY'!$Q$6:$Q$105,'DECOR INVENTORY'!$O$6:$O$105,$D9)+SUMIFS('DECORATING PLAN'!$I$6:$I$65,'DECORATING PLAN'!$G$6:$G$65,$D9)+SUMIFS('TABLESCAPE + FLORALS'!$S$6:$S$65,'TABLESCAPE + FLORALS'!$Q$6:$Q$65,$D9)+SUMIFS('TRAVEL PLAN'!$N$6:$N$45,'TRAVEL PLAN'!$L$6:$L$45,$D9)+SUMIFS('VENDORS + APPOINTMENTS'!$Q$6:$Q$65,'VENDORS + APPOINTMENTS'!$L$6:$L$65,$D9)+SUMIFS('EVENTS + WARDROBE'!$O$6:$O$65,'EVENTS + WARDROBE'!$M$6:$M$65,$D9)+SUMIFS('GROCERY LIST'!$M$6:$M$205,'GROCERY LIST'!$K$6:$K$205,$D9)+SUMIFS('MEAL + BAKING PLAN'!$R$6:$R$155,'MEAL + BAKING PLAN'!$P$6:$P$155,$D9)+SUMIFS('TRADITIONS + BUCKET LIST'!$J$6:$J$85,'TRADITIONS + BUCKET LIST'!$H$6:$H$85,$D9)-SUMIFS('RETURNS + EXCHANGES'!$R$6:$R$65,'RETURNS + EXCHANGES'!$K$6:$K$65,$D9)) | H9: =IF($D9="","",$E9-$G9) | I9: =IF($D9="","",IF($E9=0,0,$G9/$E9)) | J9: =IF($D9="","",IF(AND($E9=0,$G9=0),"NOT SET",IF($G9>$E9,"OVER BUDGET",IF($G9=$E9,"AT BUDGET",IF(AND($E9>0,$G9/$E9>=Set_WarnThreshold),"NEAR LIMIT","ON TRACK"))))) | K9: EXAMPLE FIGURE — type your own over it | L9: =IF(AND($C9="Yes",$D9<>"",OR(N($E9)>0,N($G9)>0)),$E9+(100-ROW())/10000,"") | M9: =IF($B9="",0,IF(COUNTIF('MASTER BUDGET'!$B$6:$B$25,$B9)>1,1,0))
B10: B-005 | C10: Yes | D10: Cards & Postage | E10: 150 | F10: =IF($D10="","",SUMIFS('CARDS + MAIL'!$I$6:$I$155,'CARDS + MAIL'!$H$6:$H$155,$D10)+SUMIFS('DONATIONS + GIVING'!$G$6:$G$65,'DONATIONS + GIVING'!$F$6:$F$65,$D10)+SUMIFS('GIFT PLANNER'!$Q$6:$Q$205,'GIFT PLANNER'!$G$6:$G$205,$D10)+SUMIFS('STOCKING STUFFERS'!$J$6:$J$155,'STOCKING STUFFERS'!$F$6:$F$155,$D10)+SUMIFS('CHRISTMAS CALENDAR'!$K$6:$K$205,'CHRISTMAS CALENDAR'!$J$6:$J$205,$D10)+SUMIFS('DECOR INVENTORY'!$P$6:$P$105,'DECOR INVENTORY'!$O$6:$O$105,$D10)+SUMIFS('DECORATING PLAN'!$H$6:$H$65,'DECORATING PLAN'!$G$6:$G$65,$D10)+SUMIFS('TABLESCAPE + FLORALS'!$R$6:$R$65,'TABLESCAPE + FLORALS'!$Q$6:$Q$65,$D10)+SUMIFS('TRAVEL PLAN'!$M$6:$M$45,'TRAVEL PLAN'!$L$6:$L$45,$D10)+SUMIFS('VENDORS + APPOINTMENTS'!$M$6:$M$65,'VENDORS + APPOINTMENTS'!$L$6:$L$65,$D10)+SUMIFS('EVENTS + WARDROBE'!$N$6:$N$65,'EVENTS + WARDROBE'!$M$6:$M$65,$D10)+SUMIFS('GROCERY LIST'!$L$6:$L$205,'GROCERY LIST'!$K$6:$K$205,$D10)+SUMIFS('MEAL + BAKING PLAN'!$Q$6:$Q$155,'MEAL + BAKING PLAN'!$P$6:$P$155,$D10)+SUMIFS('TRADITIONS + BUCKET LIST'!$I$6:$I$85,'TRADITIONS + BUCKET LIST'!$H$6:$H$85,$D10)) | G10: =IF($D10="","",SUMIFS('CARDS + MAIL'!$J$6:$J$155,'CARDS + MAIL'!$H$6:$H$155,$D10)+SUMIFS('DONATIONS + GIVING'!$H$6:$H$65,'DONATIONS + GIVING'!$F$6:$F$65,$D10)+SUMIFS('GIFT PLANNER'!$R$6:$R$205,'GIFT PLANNER'!$G$6:$G$205,$D10)+SUMIFS('STOCKING STUFFERS'!$K$6:$K$155,'STOCKING STUFFERS'!$F$6:$F$155,$D10)+SUMIFS('CHRISTMAS CALENDAR'!$L$6:$L$205,'CHRISTMAS CALENDAR'!$J$6:$J$205,$D10)+SUMIFS('DECOR INVENTORY'!$Q$6:$Q$105,'DECOR INVENTORY'!$O$6:$O$105,$D10)+SUMIFS('DECORATING PLAN'!$I$6:$I$65,'DECORATING PLAN'!$G$6:$G$65,$D10)+SUMIFS('TABLESCAPE + FLORALS'!$S$6:$S$65,'TABLESCAPE + FLORALS'!$Q$6:$Q$65,$D10)+SUMIFS('TRAVEL PLAN'!$N$6:$N$45,'TRAVEL PLAN'!$L$6:$L$45,$D10)+SUMIFS('VENDORS + APPOINTMENTS'!$Q$6:$Q$65,'VENDORS + APPOINTMENTS'!$L$6:$L$65,$D10)+SUMIFS('EVENTS + WARDROBE'!$O$6:$O$65,'EVENTS + WARDROBE'!$M$6:$M$65,$D10)+SUMIFS('GROCERY LIST'!$M$6:$M$205,'GROCERY LIST'!$K$6:$K$205,$D10)+SUMIFS('MEAL + BAKING PLAN'!$R$6:$R$155,'MEAL + BAKING PLAN'!$P$6:$P$155,$D10)+SUMIFS('TRADITIONS + BUCKET LIST'!$J$6:$J$85,'TRADITIONS + BUCKET LIST'!$H$6:$H$85,$D10)-SUMIFS('RETURNS + EXCHANGES'!$R$6:$R$65,'RETURNS + EXCHANGES'!$K$6:$K$65,$D10)) | H10: =IF($D10="","",$E10-$G10) | I10: =IF($D10="","",IF($E10=0,0,$G10/$E10)) | J10: =IF($D10="","",IF(AND($E10=0,$G10=0),"NOT SET",IF($G10>$E10,"OVER BUDGET",IF($G10=$E10,"AT BUDGET",IF(AND($E10>0,$G10/$E10>=Set_WarnThreshold),"NEAR LIMIT","ON TRACK"))))) | K10: EXAMPLE FIGURE — type your own over it | L10: =IF(AND($C10="Yes",$D10<>"",OR(N($E10)>0,N($G10)>0)),$E10+(100-ROW())/10000,"") | M10: =IF($B10="",0,IF(COUNTIF('MASTER BUDGET'!$B$6:$B$25,$B10)>1,1,0))
B11: B-006 | C11: Yes | D11: Events | E11: 700 | F11: =IF($D11="","",SUMIFS('CARDS + MAIL'!$I$6:$I$155,'CARDS + MAIL'!$H$6:$H$155,$D11)+SUMIFS('DONATIONS + GIVING'!$G$6:$G$65,'DONATIONS + GIVING'!$F$6:$F$65,$D11)+SUMIFS('GIFT PLANNER'!$Q$6:$Q$205,'GIFT PLANNER'!$G$6:$G$205,$D11)+SUMIFS('STOCKING STUFFERS'!$J$6:$J$155,'STOCKING STUFFERS'!$F$6:$F$155,$D11)+SUMIFS('CHRISTMAS CALENDAR'!$K$6:$K$205,'CHRISTMAS CALENDAR'!$J$6:$J$205,$D11)+SUMIFS('DECOR INVENTORY'!$P$6:$P$105,'DECOR INVENTORY'!$O$6:$O$105,$D11)+SUMIFS('DECORATING PLAN'!$H$6:$H$65,'DECORATING PLAN'!$G$6:$G$65,$D11)+SUMIFS('TABLESCAPE + FLORALS'!$R$6:$R$65,'TABLESCAPE + FLORALS'!$Q$6:$Q$65,$D11)+SUMIFS('TRAVEL PLAN'!$M$6:$M$45,'TRAVEL PLAN'!$L$6:$L$45,$D11)+SUMIFS('VENDORS + APPOINTMENTS'!$M$6:$M$65,'VENDORS + APPOINTMENTS'!$L$6:$L$65,$D11)+SUMIFS('EVENTS + WARDROBE'!$N$6:$N$65,'EVENTS + WARDROBE'!$M$6:$M$65,$D11)+SUMIFS('GROCERY LIST'!$L$6:$L$205,'GROCERY LIST'!$K$6:$K$205,$D11)+SUMIFS('MEAL + BAKING PLAN'!$Q$6:$Q$155,'MEAL + BAKING PLAN'!$P$6:$P$155,$D11)+SUMIFS('TRADITIONS + BUCKET LIST'!$I$6:$I$85,'TRADITIONS + BUCKET LIST'!$H$6:$H$85,$D11)) | G11: =IF($D11="","",SUMIFS('CARDS + MAIL'!$J$6:$J$155,'CARDS + MAIL'!$H$6:$H$155,$D11)+SUMIFS('DONATIONS + GIVING'!$H$6:$H$65,'DONATIONS + GIVING'!$F$6:$F$65,$D11)+SUMIFS('GIFT PLANNER'!$R$6:$R$205,'GIFT PLANNER'!$G$6:$G$205,$D11)+SUMIFS('STOCKING STUFFERS'!$K$6:$K$155,'STOCKING STUFFERS'!$F$6:$F$155,$D11)+SUMIFS('CHRISTMAS CALENDAR'!$L$6:$L$205,'CHRISTMAS CALENDAR'!$J$6:$J$205,$D11)+SUMIFS('DECOR INVENTORY'!$Q$6:$Q$105,'DECOR INVENTORY'!$O$6:$O$105,$D11)+SUMIFS('DECORATING PLAN'!$I$6:$I$65,'DECORATING PLAN'!$G$6:$G$65,$D11)+SUMIFS('TABLESCAPE + FLORALS'!$S$6:$S$65,'TABLESCAPE + FLORALS'!$Q$6:$Q$65,$D11)+SUMIFS('TRAVEL PLAN'!$N$6:$N$45,'TRAVEL PLAN'!$L$6:$L$45,$D11)+SUMIFS('VENDORS + APPOINTMENTS'!$Q$6:$Q$65,'VENDORS + APPOINTMENTS'!$L$6:$L$65,$D11)+SUMIFS('EVENTS + WARDROBE'!$O$6:$O$65,'EVENTS + WARDROBE'!$M$6:$M$65,$D11)+SUMIFS('GROCERY LIST'!$M$6:$M$205,'GROCERY LIST'!$K$6:$K$205,$D11)+SUMIFS('MEAL + BAKING PLAN'!$R$6:$R$155,'MEAL + BAKING PLAN'!$P$6:$P$155,$D11)+SUMIFS('TRADITIONS + BUCKET LIST'!$J$6:$J$85,'TRADITIONS + BUCKET LIST'!$H$6:$H$85,$D11)-SUMIFS('RETURNS + EXCHANGES'!$R$6:$R$65,'RETURNS + EXCHANGES'!$K$6:$K$65,$D11)) | H11: =IF($D11="","",$E11-$G11) | I11: =IF($D11="","",IF($E11=0,0,$G11/$E11)) | J11: =IF($D11="","",IF(AND($E11=0,$G11=0),"NOT SET",IF($G11>$E11,"OVER BUDGET",IF($G11=$E11,"AT BUDGET",IF(AND($E11>0,$G11/$E11>=Set_WarnThreshold),"NEAR LIMIT","ON TRACK"))))) | K11: EXAMPLE FIGURE — type your own over it | L11: =IF(AND($C11="Yes",$D11<>"",OR(N($E11)>0,N($G11)>0)),$E11+(100-ROW())/10000,"") | M11: =IF($B11="",0,IF(COUNTIF('MASTER BUDGET'!$B$6:$B$25,$B11)>1,1,0))
